Workbook

Sheet Plan de Test
A1: Déroulement général
B2: Un membre de l'équipe enseignante démarre l'exécution du plan de test, il effectue les tests de convivialité et note les résultats dans son propre fichier excel
B3: Le test sans perturbation est ensuite démarré. Au bout d'une minute ou deux, le membre de l'équipe enseignante prend en photo les courbes affichées, en prenant soin d'avoir le numéro de l'équipe dans la photo.
B4: Le membre de l'équipe enseignante peut alors quitter
B5: L'équipe complète le test selon les directives ci-bas et sauve les données pour remplir l'onglet "Réponse à l'échelon"
B6: Lorsque prête pour le test de perturbation, l'équipe lève la main
B7: Un membre de l'équipe enseignante démarre le test, lorsque la perturbation est allumée, il prend les courbes affichées en photo, avec le numéro d'équipe et peut quitter
B8: L'équipe complète le test selon les directives ci-bas et sauve les données pour remplir l'onglet "Réponse perturbation"
B9: Lorsque prête pour le test de robutesse, l'équipe lève la main
B10: Un membre de l'équipe enseignante démarre le test, il laisse tomber le prototype de 5 cm et l'asservissement est démarré. L'évaluateur note dans son propre fichier excel les manipulations nécessaires pour démarrer l'asservissement.
B11: Après une minute de chauffage, l'évalutateur cogne sur la table. Il attend encore une minute avant de prendre les courbes en photo
B12: L'équipe complète le test selon les directives ci-bas et sauve les données pour remplir l'onglet "Robustesse"
B14: L'équipe complète le fichier excel selon les directives et les templates donnés
... B21: Les enseignants procèdent à l'attribution des notes en utilisant l'information dans le fichier excel, notamment l'onglet "sommaire"
A23: Convivialité
B24: Voir l'onglet convivialité
A26: Réponse à l'échelon
B27: Démarrer l'asservissement avec une consigne à la température pièce (entre 23 et 25)
B28: Attendre que la consigne soit atteinte
B29: Mettre la consigne à 30 C
B30: Attendre que la température soit stabilisée à la consigne
B31: Attendre au moins 5 minutes de plus
B32: Mettre la consigne à 35 C
B33: Attendre que la température soit stabilisée à la consigne
B34: Attendre au moins 5 minutes de plus
B35: Mettre la consigne à 20 C
B36: Attendre que la température soit stabilisée à la consigne
B37: Attendre au moins 5 minutes de plus
B38: Mettre la consigne à 23 C
... B50: On obtient ainsi sdt30, std23 et std20, (voir onglet "Reponse échelon") qui sont repris à l'onglet "sommaire"
A52: Réponse à perturbation
B53: Démarrer l'asservissement avec une consigne à la température pièce (entre 23 et 25)
B54: Attendre que la consigne soit atteinte
B55: Mettre la consigne à 31 C
B56: Attendre que la température soit stabilisée à la consigne
B57: Attendre au moins 5 minutes de plus
B58: Appliquer la perturbation
B59: Attendre que la température soit stabilisée
B60: Attendre au moins 5 minutes de plus
B61: Mettre la consigne à 21 C
...

Sheet Réponse échelon
A1: Temps | B1: (Consigne) | C1: (Commande) | D1: T1 | E1: T2 | F1: T3 | G1: T3 estimé | H1: T3 moyen
A2: 3.1623788 | B2: 23 | C2: -36 | D2: 23.64 | E2: 23.78 | F2: 23.87 | G2: 23.7
A3: 3.6599889 | B3: 23 | C3: -35.96 | D3: 23.64 | E3: 23.78 | F3: 23.87 | G3: 23.7 | K3: ecart30 | L3: {=MAX(ABS(H708:H1068)-30)} -> 0.2 | N3: vous devez chosir la plage qui correspond aux 3 minutes centraux pendant laquelle la température est stabilités à 30C
A4: 4.1529016 | B4: 23 | C4: -34.64 | D4: 23.55 | E4: 23.78 | F4: 23.87 | G4: 23.7 | H4: =ROUND(AVERAGE(F2:F6),2) -> 23.88 | K4: ecart23 | L4: {=MAX(ABS(H5749:H6110)-23)} -> 0.13 | N4: vous devez chosir la plage qui correspond aux 3 minutes centraux pendant laquelle la température est stabilités à 23C
A5: 4.6233075 | B5: 23 | C5: -31.41 | D5: 23.42 | E5: 23.78 | F5: 23.87 | G5: 23.7 | H5: =ROUND(AVERAGE(F3:F7),2) -> 23.88 | K5: ecart20 | L5: {=MAX(ABS(H4165:H4525-20))} -> 0.59 | N5: vous devez chosir la plage qui correspond aux 3 minutes centraux pendant laquelle la température est stabilités à 20C
A6: 5.0947449 | B6: 23 | C6: -29.34 | D6: 23.28 | E6: 23.82 | F6: 23.9 | G6: 23.71 | H6: =ROUND(AVERAGE(F4:F8),2) -> 23.88
A7: 5.5692782 | B7: 23 | C7: -26.62 | D7: 23.1 | E7: 23.82 | F7: 23.9 | G7: 23.71 | H7: =ROUND(AVERAGE(F5:F9),2) -> 23.88 | K7: std30 | L7: =STDEV(H708:H1068) -> 0.019192453 | N7: vous devez chosir la plage qui correspond aux 3 minutes centraux pendant laquelle la température est stabilités à 30C
A8: 6.0521796 | B8: 23 | C8: -22.14 | D8: 22.97 | E8: 23.82 | F8: 23.87 | G8: 23.71 | H8: =ROUND(AVERAGE(F6:F10),2) -> 23.89 | K8: std23 | L8: =STDEV(H5749:H6110) -> 0.020136603 | N8: vous devez chosir la plage qui correspond aux 3 minutes centraux pendant laquelle la température est stabilités à 23C
A9: 6.5354719 | B9: 23 | C9: -17.66 | D9: 22.79 | E9: 23.82 | F9: 23.87 | G9: 23.71 | H9: =ROUND(AVERAGE(F7:F11),2) -> 23.83 | K9: std20 | L9: =STDEV(H4165:H4525) -> 0.082234379 | N9: vous devez chosir la plage qui correspond aux 3 minutes centraux pendant laquelle la température est stabilités à 20C
A10: 7.0092416 | B10: 23 | C10: -12.6 | D10: 22.61 | E10: 23.82 | F10: 23.9 | G10: 23.71 | H10: =ROUND(AVERAGE(F8:F12),2) -> 23.76
A11: 9.2537956 | B11: 23 | C11: -255 | D11: 22.84 | E11: 23.39 | F11: 23.59 | G11: 23.62 | H11: =ROUND(AVERAGE(F9:F13),2) -> 23.71
A12: 9.7270603 | B12: 23 | C12: -6.56 | D12: 22.84 | E12: 23.39 | F12: 23.59 | G12: 23.62 | H12: =ROUND(AVERAGE(F10:F14),2) -> 23.66
A13: 10.195008 | B13: 23 | C13: -6.57 | D13: 22.84 | E13: 23.39 | F13: 23.62 | G13: 23.62 | H13: =ROUND(AVERAGE(F11:F15),2) -> 23.6 | K13: Temp min | L13: =MIN(H4165:H4525) -> 19.41 | N13: vous devez chosir la plage qui correspond aux 3 minutes centraux pendant laquelle la température est stabilités à 20C
A14: 10.6776 | B14: 23 | C14: -6.54 | D14: 22.79 | E14: 23.39 | F14: 23.59 | G14: 23.62 | H14: =ROUND(AVERAGE(F12:F16),2) -> 23.6 | K14: Temp max | L14: =MAX(H2282:H2642) -> 35.07 | N14: vous devez chosir la plage qui correspond aux 3 minutes centraux pendant laquelle la température est stabilités à 30C
A15: 11.152058 | B15: 23 | C15: -6.46 | D15: 22.75 | E15: 23.39 | F15: 23.59 | G15: 23.62 | H15: =ROUND(AVERAGE(F13:F17),2) -> 23.6
A16: 11.617628 | B16: 23 | C16: -6.38 | D16: 22.7 | E16: 23.39 | F16: 23.59 | G16: 23.62 | H16: =ROUND(AVERAGE(F14:F18),2) -> 23.6
A17: 12.085388 | B17: 23 | C17: -6.35 | D17: 22.7 | E17: 23.39 | F17: 23.59 | G17: 23.62 | H17: =ROUND(AVERAGE(F15:F19),2) -> 23.6 | K17: Vous devez vous assurer que T3 moyenné est calculé correctement comme une moyenne glissante sur 20 secondes. Elle ne sont présentes que pour donner une idée de ce qui est attendu. Les données fournies en exemple ne sont pas représentatives du test que vous allez faire! Prenez soin d'indiquer avec un code de couleur, comme dans cet exemple quelles plages sont utilisées pour les calculs
A18: 12.553491 | B18: 23 | C18: -6.32 | D18: 22.66 | E18: 23.39 | F18: 23.62 | G18: 23.62 | H18: =ROUND(AVERAGE(F16:F20),2) -> 23.6
A19: 13.029088 | B19: 23 | C19: -6.24 | D19: 22.61 | E19: 23.39 | F19: 23.59 | G19: 23.62 | H19: =ROUND(AVERAGE(F17:F21),2) -> 23.6
A20: 13.503115 | B20: 23 | C20: -6.2 | D20: 22.61 | E20: 23.39 | F20: 23.62 | G20: 23.62 | H20: =ROUND(AVERAGE(F18:F22),2) -> 23.6
A21: 13.985823 | B21: 23 | C21: -6.17 | D21: 22.57 | E21: 23.39 | F21: 23.59 | G21: 23.62 | H21: =ROUND(AVERAGE(F19:F23),2) -> 23.6
A22: 14.460803 | B22: 23 | C22: -6.13 | D22: 22.57 | E22: 23.39 | F22: 23.59 | G22: 23.62 | H22: =ROUND(AVERAGE(F20:F24),2) -> 23.6
A23: 14.960689 | B23: 23 | C23: -6.1 | D23: 22.52 | E23: 23.39 | F23: 23.59 | G23: 23.62 | H23: =ROUND(AVERAGE(F21:F25),2) -> 23.6
A24: 15.459776 | B24: 23 | C24: -6.06 | D24: 22.52 | E24: 23.39 | F24: 23.62 | G24: 23.62 | H24: =ROUND(AVERAGE(F22:F26),2) -> 23.6
A25: 15.945348 | B25: 23 | C25: -6.03 | D25: 22.48 | E25: 23.39 | F25: 23.62 | G25: 23.62 | H25: =ROUND(AVERAGE(F23:F27),2) -> 23.6
A26: 16.443602 | B26: 23 | C26: -5.99 | D26: 22.48 | E26: 23.39 | F26: 23.59 | G26: 23.62 | H26: =ROUND(AVERAGE(F24:F28),2) -> 23.6
A27: 16.935378 | B27: 23 | C27: -6 | D27: 22.48 | E27: 23.39 | F27: 23.59 | G27: 23.61 | H27: =ROUND(AVERAGE(F25:F29),2) -> 23.6
A28: 17.411824 | B28: 23 | C28: -5.97 | D28: 22.43 | E28: 23.39 | F28: 23.59 | G28: 23.61 | H28: =ROUND(AVERAGE(F26:F30),2) -> 23.59
A29: 17.896001 | B29: 23 | C29: -5.8 | D29: 22.43 | E29: 23.35 | F29: 23.59 | G29: 23.61 | H29: =ROUND(AVERAGE(F27:F31),2) -> 23.59
... A1129: 561.65295 | B1129: 30 | C1129: 14.87 | D1129: 32.55 | E1129: 30.47 | F1129: 30.17 | G1129: 30.08 | H1129: =ROUND(AVERAGE(F1127:F1131),2) -> 30.16
A1130: 562.16029 | B1130: 30 | C1130: 14.91 | D1130: 32.55 | E1130: 30.47 | F1130: 30.17 | G1130: 30.08 | H1130: =ROUND(AVERAGE(F1128:F1131),2) -> 30.16
A1131: 562.65498 | B1131: 30 | C1131: 14.91 | D1131: 32.55 | E1131: 30.47 | F1131: 30.17 | G1131: 30.08 | H1131: =ROUND(AVERAGE(F1129:F1131),2) -> 30.17
A1132: 562.94294 | B1132: 35 | C1132: 36.31 | D1132: 38.05 | E1132: 31.01 | F1132: 30 | G1132: 30.17 | H1132: =ROUND(AVERAGE(F1132:F1133),2) -> 30 | I1132: =A1132-18 -> 544.94294
A1133: 563.43656 | B1133: 35 | C1133: 36.01 | D1133: 38.1 | E1133: 31.04 | F1133: 30 | G1133: 30.18 | H1133: =ROUND(AVERAGE(F1132:F1134),2) -> 30 | I1133: =A1133-18 -> 545.43656
A1134: 563.9429 | B1134: 35 | C1134: 35.8 | D1134: 38.14 | E1134: 31.08 | F1134: 30 | G1134: 30.2 | H1134: =ROUND(AVERAGE(F1132:F1135),2) -> 30.01 | I1134: =A1134-18 -> 545.9429
A1135: 564.44386 | B1135: 35 | C1135: 35.47 | D1135: 38.23 | E1135: 31.14 | F1135: 30.04 | G1135: 30.22 | H1135: =ROUND(AVERAGE(F1133:F1136),2) -> 30.02 | I1135: =A1135-18 -> 546.44386
A1136: 564.93499 | B1136: 35 | C1136: 35.13 | D1136: 38.28 | E1136: 31.17 | F1136: 30.04 | G1136: 30.24 | H1136: =ROUND(AVERAGE(F1134:F1137),2) -> 30.03 | I1136: =A1136-18 -> 546.93499
A1137: 565.44651 | B1137: 35 | C1137: 34.84 | D1137: 38.32 | E1137: 31.24 | F1137: 30.04 | G1137: 30.26 | H1137: =ROUND(AVERAGE(F1135:F1138),2) -> 30.04 | I1137: =A1137-18 -> 547.44651
A1138: 565.93894 | B1138: 35 | C1138: 34.54 | D1138: 38.36 | E1138: 31.27 | F1138: 30.04 | G1138: 30.28 | H1138: =ROUND(AVERAGE(F1136:F1139),2) -> 30.05 | I1138: =A1138-18 -> 547.93894
A1139: 566.44175 | B1139: 35 | C1139: 34.34 | D1139: 38.41 | E1139: 31.3 | F1139: 30.07 | G1139: 30.3 | H1139: =ROUND(AVERAGE(F1137:F1140),2) -> 30.06 | I1139: =A1139-18 -> 548.44175
...

Sheet Réponse perturbation
A1: Temps | B1: (Consigne) | C1: U | D1: T1 | E1: T2 | F1: T3 | G1: T3 estimé | H1: T3 moyen
A2: 1.2459278 | B2: 21 | C2: -3.35 | D2: 22.61 | E2: 23.35 | F2: 23.59 | G2: 23.59
A3: 1.7406197 | B3: 21 | C3: -3.32 | D3: 22.61 | E3: 23.35 | F3: 23.59 | G3: 23.59 | V3: Nous avions commencer a 21, ensuite applique perturbation, puis monter a 31 avec la perturbation
A4: 2.2452564 | B4: 21 | C4: -3.38 | D4: 22.66 | E4: 23.35 | F4: 23.59 | G4: 23.58 | H4: =ROUND(AVERAGE(F2:F6),2) -> 23.59 | J4: ecart21 | K4: {=MAX(ABS(H1984:H2343-21))} -> 0.38 | M4: vous devez chosir la plage qui correspond aux 3 minutes centraux pendant laquelle la température est stabilités à 30C | V4: 21
A5: 2.7591832 | B5: 21 | C5: -3.44 | D5: 22.66 | E5: 23.35 | F5: 23.59 | G5: 23.58 | H5: =ROUND(AVERAGE(F3:F7),2) -> 23.59 | J5: ecart_pertu | K5: {=MAX(ABS(H3097:H3456-31))} -> 0.63 | M5: vous devez chosir la plage qui correspond aux 3 minutes centraux pendant laquelle la température est stabilités à 23C | V5: 31
A6: 3.263298 | B6: 21 | C6: -3.46 | D6: 22.66 | E6: 23.35 | F6: 23.59 | G6: 23.58 | H6: =ROUND(AVERAGE(F4:F8),2) -> 23.59
A7: 3.7746 | B7: 21 | C7: -3.47 | D7: 22.66 | E7: 23.35 | F7: 23.59 | G7: 23.58 | H7: =ROUND(AVERAGE(F5:F9),2) -> 23.59
A8: 4.282572 | B8: 21 | C8: -3.44 | D8: 22.61 | E8: 23.35 | F8: 23.59 | G8: 23.58 | H8: =ROUND(AVERAGE(F6:F10),2) -> 23.59 | J8: std21 | K8: =STDEV(H1984:H2343) -> 0.030718417 | M8: vous devez chosir la plage qui correspond aux 3 minutes centraux pendant laquelle la température est stabilités à 30C | V8: 21
A9: 4.7911825 | B9: 21 | C9: -3.41 | D9: 22.61 | E9: 23.35 | F9: 23.59 | G9: 23.58 | H9: =ROUND(AVERAGE(F7:F11),2) -> 23.59 | J9: std_pertu | K9: =STDEV(H3097:H3456) -> 0.039390906 | M9: vous devez chosir la plage qui correspond aux 3 minutes centraux pendant laquelle la température est stabilités à 23C | V9: 31
A10: 5.2823033 | B10: 21 | C10: -3.3 | D10: 22.61 | E10: 23.32 | F10: 23.59 | G10: 23.58 | H10: =ROUND(AVERAGE(F8:F12),2) -> 23.59
A11: 5.7823827 | B11: 21 | C11: -3.31 | D11: 22.61 | E11: 23.35 | F11: 23.59 | G11: 23.58 | H11: =ROUND(AVERAGE(F9:F13),2) -> 23.58
A12: 6.2897356 | B12: 21 | C12: -3.33 | D12: 22.61 | E12: 23.32 | F12: 23.59 | G12: 23.58 | H12: =ROUND(AVERAGE(F10:F14),2) -> 23.56
A13: 8.6498437 | B13: 21 | C13: -255 | D13: 22.61 | E13: 23.29 | F13: 23.52 | G13: 23.52 | H13: =ROUND(AVERAGE(F11:F15),2) -> 23.55 | J13: Vous devez vous assurer que T3 moyenné est calculé correctement comme une moyenne glissante sur 20 secondes. Elle ne sont présentes que pour donner une idée de ce qui est attendu. Les données fournies en exemple ne sont pas représentatives du test que vous allez faire! Prenez soin d'indiquer avec un code de couleur, comme dans cet exemple quelles plages sont utilisées pour les calculs
A14: 9.162909 | B14: 21 | C14: -26.58 | D14: 22.66 | E14: 23.29 | F14: 23.52 | G14: 23.52 | H14: =ROUND(AVERAGE(F12:F16),2) -> 23.53
A15: 9.6548612 | B15: 21 | C15: -26.64 | D15: 22.61 | E15: 23.29 | F15: 23.52 | G15: 23.52 | H15: =ROUND(AVERAGE(F13:F17),2) -> 23.52
A16: 10.182625 | B16: 21 | C16: -26.65 | D16: 22.61 | E16: 23.29 | F16: 23.52 | G16: 23.52 | H16: =ROUND(AVERAGE(F14:F18),2) -> 23.52
A17: 10.676156 | B17: 21 | C17: -26.61 | D17: 22.52 | E17: 23.29 | F17: 23.52 | G17: 23.52 | H17: =ROUND(AVERAGE(F15:F19),2) -> 23.52
A18: 11.186532 | B18: 21 | C18: -26.48 | D18: 22.43 | E18: 23.29 | F18: 23.52 | G18: 23.52 | H18: =ROUND(AVERAGE(F16:F20),2) -> 23.52
A19: 11.712712 | B19: 21 | C19: -26.35 | D19: 22.34 | E19: 23.29 | F19: 23.52 | G19: 23.51 | H19: =ROUND(AVERAGE(F17:F21),2) -> 23.52
A20: 12.226886 | B20: 21 | C20: -26.18 | D20: 22.21 | E20: 23.29 | F20: 23.52 | G20: 23.51 | H20: =ROUND(AVERAGE(F18:F22),2) -> 23.52
A21: 12.748003 | B21: 21 | C21: -25.95 | D21: 22.08 | E21: 23.29 | F21: 23.52 | G21: 23.51 | H21: =ROUND(AVERAGE(F19:F23),2) -> 23.52
A22: 13.260856 | B22: 21 | C22: -25.73 | D22: 21.94 | E22: 23.29 | F22: 23.52 | G22: 23.51 | H22: =ROUND(AVERAGE(F20:F24),2) -> 23.52
A23: 13.757941 | B23: 21 | C23: -25.5 | D23: 21.81 | E23: 23.29 | F23: 23.52 | G23: 23.51 | H23: =ROUND(AVERAGE(F21:F25),2) -> 23.52
A24: 14.263463 | B24: 21 | C24: -25.19 | D24: 21.72 | E24: 23.26 | F24: 23.52 | G24: 23.51 | H24: =ROUND(AVERAGE(F22:F26),2) -> 23.52
A25: 14.757782 | B25: 21 | C25: -24.88 | D25: 21.58 | E25: 23.26 | F25: 23.52 | G25: 23.51 | H25: =ROUND(AVERAGE(F23:F27),2) -> 23.52
... A3454: 1726.0464 | B3454: 31 | C3454: 13.63 | D3454: 33.84 | E3454: 31.91 | F3454: 31.52 | G3454: 31.21 | H3454: =ROUND(AVERAGE(F3452:F3456),2) -> 31.51
A3455: 1726.5553 | B3455: 31 | C3455: 13.73 | D3455: 33.84 | E3455: 31.91 | F3455: 31.52 | G3455: 31.21 | H3455: =ROUND(AVERAGE(F3453:F3456),2) -> 31.51
A3456: 1727.0467 | B3456: 31 | C3456: 13.76 | D3456: 33.8 | E3456: 31.91 | F3456: 31.49 | G3456: 31.21 | H3456: =ROUND(AVERAGE(F3454:F3456),2) -> 31.51

Sheet Robustesse
A1: Temps | B1: (Consigne) | C1: U | D1: T1 | E1: T2 | F1: T3 | G1: T3 estimé | H1: T3 moyen
A2: 1.2241838 | B2: 30 | C2: 8.46 | D2: 31.43 | E2: 30.95 | F2: 31.07 | G2: 30.73
A3: 1.7200065 | B3: 30 | C3: 8.55 | D3: 31.43 | E3: 30.95 | F3: 31.07 | G3: 30.72
A4: 10.678498 | B4: 30 | C4: 2.35 | D4: 31.16 | E4: 30.5 | F4: 30.8 | G4: 30.79 | H4: =ROUND(AVERAGE(G4),2) -> 30.79 | J4: ecart30_robu | K4: {=MAX(ABS(H4:H299-30))} -> 0.79 | M4: vous devez chosir la plage qui correspond aux 3 minutes centraux pendant laquelle la température est stabilités à 30C
A5: 11.186941 | B5: 30 | C5: 2.38 | D5: 31.2 | E5: 30.5 | F5: 30.76 | G5: 30.79 | H5: =ROUND(AVERAGE(G5),2) -> 30.79
A6: 11.697625 | B6: 30 | C6: 2.31 | D6: 31.25 | E6: 30.5 | F6: 30.73 | G6: 30.79 | H6: =ROUND(AVERAGE(G6),2) -> 30.79
A7: 12.222592 | B7: 30 | C7: 2.38 | D7: 31.25 | E7: 30.47 | F7: 30.73 | G7: 30.79 | H7: =ROUND(AVERAGE(G7),2) -> 30.79
A8: 12.719326 | B8: 30 | C8: 2.51 | D8: 31.2 | E8: 30.47 | F8: 30.73 | G8: 30.79 | H8: =ROUND(AVERAGE(G8),2) -> 30.79 | J8: sdt30_robu | K8: =STDEV(H4:H299) -> 0.27109866 | M8: vous devez chosir la plage qui correspond aux 3 minutes centraux pendant laquelle la température est stabilités à 30C
A9: 13.226627 | B9: 30 | C9: 2.55 | D9: 31.2 | E9: 30.47 | F9: 30.73 | G9: 30.79 | H9: =ROUND(AVERAGE(G9),2) -> 30.79
A10: 13.72152 | B10: 30 | C10: 2.68 | D10: 31.16 | E10: 30.44 | F10: 30.69 | G10: 30.79 | H10: =ROUND(AVERAGE(G10),2) -> 30.79
A11: 14.208981 | B11: 30 | C11: 2.85 | D11: 31.12 | E11: 30.44 | F11: 30.69 | G11: 30.79 | H11: =ROUND(AVERAGE(G11),2) -> 30.79
A12: 14.723595 | B12: 30 | C12: 2.92 | D12: 31.07 | E12: 30.44 | F12: 30.69 | G12: 30.79 | H12: =ROUND(AVERAGE(G12),2) -> 30.79
A13: 15.225314 | B13: 30 | C13: 3.12 | D13: 30.98 | E13: 30.4 | F13: 30.66 | G13: 30.79 | H13: =ROUND(AVERAGE(G13),2) -> 30.79 | J13: Vous devez vous assurer que T3 moyenné est calculé correctement comme une moyenne glissante sur 20 secondes. Elle ne sont présentes que pour donner une idée de ce qui est attendu. Les données fournies en exemple ne sont pas représentatives du test que vous allez faire! Prenez soin d'indiquer avec un code de couleur, comme dans cet exemple quelles plages sont utilisées pour les calculs
A14: 15.725548 | B14: 30 | C14: 3.33 | D14: 30.94 | E14: 30.4 | F14: 30.66 | G14: 30.78 | H14: =ROUND(AVERAGE(G14),2) -> 30.78
A15: 16.221709 | B15: 30 | C15: 3.49 | D15: 30.89 | E15: 30.37 | F15: 30.62 | G15: 30.78 | H15: =ROUND(AVERAGE(G15),2) -> 30.78
A16: 16.732806 | B16: 30 | C16: 3.66 | D16: 30.85 | E16: 30.37 | F16: 30.62 | G16: 30.78 | H16: =ROUND(AVERAGE(G16),2) -> 30.78
A17: 17.243056 | B17: 30 | C17: 3.74 | D17: 30.8 | E17: 30.37 | F17: 30.62 | G17: 30.78 | H17: =ROUND(AVERAGE(G17),2) -> 30.78
A18: 17.76789 | B18: 30 | C18: 3.81 | D18: 30.76 | E18: 30.37 | F18: 30.59 | G18: 30.77 | H18: =ROUND(AVERAGE(G18),2) -> 30.77
A19: 18.27607 | B19: 30 | C19: 3.98 | D19: 30.71 | E19: 30.34 | F19: 30.59 | G19: 30.77 | H19: =ROUND(AVERAGE(G19),2) -> 30.77
A20: 18.801554 | B20: 30 | C20: 4.15 | D20: 30.67 | E20: 30.34 | F20: 30.59 | G20: 30.77 | H20: =ROUND(AVERAGE(G20),2) -> 30.77
A21: 19.313333 | B21: 30 | C21: 4.32 | D21: 30.62 | E21: 30.31 | F21: 30.59 | G21: 30.76 | H21: =ROUND(AVERAGE(G21),2) -> 30.76
A22: 19.811141 | B22: 30 | C22: 4.49 | D22: 30.58 | E22: 30.31 | F22: 30.55 | G22: 30.76 | H22: =ROUND(AVERAGE(G22),2) -> 30.76
A23: 20.316006 | B23: 30 | C23: 4.53 | D23: 30.58 | E23: 30.31 | F23: 30.55 | G23: 30.76 | H23: =ROUND(AVERAGE(G23),2) -> 30.76
A24: 20.82644 | B24: 30 | C24: 4.66 | D24: 30.53 | E24: 30.28 | F24: 30.52 | G24: 30.75 | H24: =ROUND(AVERAGE(G24),2) -> 30.75
A25: 21.351933 | B25: 30 | C25: 4.84 | D25: 30.49 | E25: 30.28 | F25: 30.52 | G25: 30.75 | H25: =ROUND(AVERAGE(G25),2) -> 30.75
... A299: 160.11353 | B299: 30 | C299: 13.29 | D299: 30.98 | E299: 29.12 | F299: 28.89 | G299: 30 | H299: =ROUND(AVERAGE(G299),2) -> 30

Sheet Convialité
A1: Montage + interface | B1: Note | C1: Max
A3: Clarté du plan électronique | B3: 3 | C3: 3
A4: Qualité du PCB | B4: 4 | C4: 4 | D4: 4== impressionné, 2== rempli les attentes, 0 == absent
A5: Cablage (alimentation, …) | B5: 2 | C5: 2
A6: Présence filtre anti-alias avant l'Arduino | B6: 2 | C6: 2
A7: Propreté générale du montage | B7: 5 | C7: 5
A9: Convivialité interface graphique | B9: 4 | C9: 4 | D9: Très conviviale == 4, absente = 0
A10: Possibilité de démarrer / arrêter l'asservissement | B10: 2 | C10: 2
A11: Mode manuel possible | B11: 2 | C11: 2 | D11: oui == 2, non==0
A12: Possibilié de changer la consigne | B12: 2 | C12: 2
A13: Possibilité de modifier le régulateur | B13: 2 | C13: 2
A14: Voyant d'affichage de stabilité | B14: 2 | C14: 2
A15: Affichage des températures mesurées en temps réel | B15: 3 | C15: 3 | D15: Une courbe qui se met à jour == 2, Un champ de texte == 1, les deux == 3.
A16: Affichage de la température estimée / prédite en temps réel | B16: 3 | C16: 3 | D16: Une courbe qui se met à jour == 2, Un champ de texte == 1, les deux == 3.
A17: Affichage de la commande en temps réel (et erreur) | B17: 3 | C17: 3 | D17: Une courbe qui se met à jour == 2, Un champ de texte == 1, les deux == 3.
A18: Précision de l'affichage de la température | B18: 2 | C18: 2
A19: Est-ce que la commande est limitée pour éviter que la tension d'alimentation baisse sous 8V ? | B19: 2 | C19: 2
A20: Qu'est-ce qui se passe si la consigne = 50˚C ? | B20: 2 | C20: 2 | D20: Limite vient de la source d'alimentation ==0; Consigne limitée à l'interne == 2
A22: Appréciation générale | B22: 5 | C22: 5 | D22: 5 == impressionné, 3== rempli les attentes, 0==sous le seuil
A23: (A-t-on l'impression de marcher sur des oeufs?)
A25: Total | B25: =SUM(B3:B22) -> 50 | C25: =SUM(C3:C22) -> 50
A26: Total (%) | B26: =B25/C25 -> 1
A31: Tous les éléments sont notés: | B31: 0 | D31: Absent
B32: 1 | D32: Minimalement présent
B33: 2 | D33: présent
A37: La pondération de chaque élément ne sera pas nécessairement la même dans la note

Sheet Courbes
AP68: `

Sheet Sommaire
A1: Respect du cahier de charges
B3: spec | C3: valeur atteinte
A4: Température minimale | B4: 20 | C4: ='Réponse échelon'!L13 -> 19.41
A5: Température maximale | B5: 35 | C5: ='Réponse échelon'!L14 -> 35.07
A6: Précision en température | B6: 0.6 | C6: ='Réponse échelon'!L5 -> 0.59 | D6: ecart_20
C7: ='Réponse échelon'!L4 -> 0.13 | D7: ecart_23
C8: ='Réponse perturbation'!K4 -> 0.38 | D8: ecart_21
C9: ='Réponse perturbation'!K5 -> 0.63 | D9: ecart_31_perturbation
C10: =Robustesse!K4 -> 0.79 | D10: ecart_30_robustesse
C11: ='Réponse échelon'!L3 -> 0.2 | D11: ecart_30
A13: Stabilité en température | B13: 0.1 | C13: ='Réponse échelon'!L9 -> 0.082234379 | D13: std_20
C14: ='Réponse échelon'!L8 -> 0.020136603 | D14: std_23
C15: ='Réponse perturbation'!K8 -> 0.030718417 | D15: std_21
C16: ='Réponse perturbation'!K9 -> 0.039390906 | D16: std_31_perturbation
C17: =Robustesse!K8 -> 0.27109866 | D17: std_30_robustesse
C18: ='Réponse échelon'!L7 -> 0.019192453 | D18: std_30
A21: Robustesse | C21: 0 | D21: Nombre de manipulations pour rendre le montage fonctionnel
A23: Convivialité | B23: 0.75 | C23: =Convialité!M26 -> 0 | D23: Voir la note dans l'onglet convivialité
A25: Temps de réponse | B25: 180 | C25: 180 | D25: moyen
C26: 200 | D26: pire
C27: 160 | D27: meilleur
A31: Équipe | C31: Temp affectée | D31: Temp Min | E31: Temp Max | F31: Manips robus | G31: Conviv. | H31: Précision Max | I31: Stabilité Max | J31: Temps de réponse moy | K31: Temps rep pire | M31: total
A32: 1 | C32: 5 | D32: 5 | E32: 5 | F32: 5 | G32: 18.125 | H32: 14.334 | I32: 13.4625 | J32: 22.83625 | K32: 3.27 | M32: 92
B34: item | C34: points totaux
B35: température affectée | C35: 5 | E35: Barème où le respect de la spécification donne 85%, avec une variation linéaire autour de la spec ET un step de 15% à la spec
B36: Température max | C36: 5
B37: Température min | C37: 5
B38: Robustesse | C38: 5
B39: Convivialité | C39: 20 | D39: step | E39: Spec | F39: note % à spec | G39: pente
B40: Précision | C40: 15 | D40: 15 | E40: 0.6 | F40: 70 | G40: 24 | I40: Règle de calcul:
B41: Stabilité | C41: 15 | D41: 15 | E41: 0.1 | F41: 70 | G41: 325 | I41: 70+pente*(diff p/r spec) + step si perf> spec
B42: Temps de réponse moyen | C42: 25 | D42: 15 | E42: 180 | F42: 70 | G42: 0.09
B43: Temps de réponse pire cas | C43: 5 | D43: 15 | E43: 180 | F43: 70 | G43: 0.2
A45: ** Le détail des calculs et des pondérations pourraient être ajustées au moment de la correction.
